Workbook

Sheet Customer information
A1: Form No. | B1: Customer Name | C1: Contact No. | D1: Gender | E1: Dress Type | F1: Order Type | G1: Booking Date | H1: Delivery Date | I1: Total Amount | J1: Advance Paid | K1: Amount Due | L1: Notes | M1: Month
A2: 2025/001 | B2: Chanu Jain | C2: 8050016045 | D2: Female | E2: Gown (Sinner Lycra Fabric) | F2: Sell | G2: 45908 | H2: 45911 | I2: 1710 | J2: 750 | K2: =I2 - J2 -> 960 | L2: Stretchable Lycra, Skirt + Flowy | M2: =TEXT(G2,"YYYY-MM") -> 2025-09
A3: 2025/002 | B3: Ankita barorer | C3: 9799223089 | D3: Female | E3: onepiece | F3: Sell | G3: 45870 | H3: 45875 | I3: 2555 | J3: 1900 | K3: =I3 - J3 -> 655 | L3: farwell ocasion | M3: =TEXT(G3,"YYYY-MM") -> 2025-08
A4: 2025/003 | B4: Shilp | C4: 7728087298 | D4: Female | E4: Serews | F4: Sell | G4: 45948 | H4: 45954 | I4: 1600 | J4: 1000 | K4: =I4 - J4 -> 600 | L4: Birthday | M4: =TEXT(G4,"YYYY-MM") -> 2025-10
A5: 2025/004 | B5: Kirti malpani | C5: 9680731821 | D5: Female | E5: lehanga top | F5: Sell | G5: 45920 | H5: 45925 | I5: 2500 | J5: 1200 | K5: =I5 - J5 -> 1300 | L5: navratri design | M5: =TEXT(G5,"YYYY-MM") -> 2025-09
A6: 2025/005 | B6: Ritu | C6: 7976124034 | D6: Female | E6: Lehanga top | F6: Rent | G6: 45911 | H6: 45911 | I6: 1000 | J6: 500 | K6: =I6 - J6 -> 500 | L6: Shadi | M6: =TEXT(G6,"YYYY-MM") -> 2025-09
A7: 2025/006 | B7: Richa | C7: 9414610876 | D7: Female | E7: Kurta | F7: Sell | G7: 45948 | H7: 45950 | I7: 2100 | J7: 1000 | K7: =I7 - J7 -> 1100 | L7: navratri design | M7: =TEXT(G7,"YYYY-MM") -> 2025-10
A8: 2025/007 | B8: Diksha | C8: 6350408191 | D8: Female | E8: Gown | F8: Sell | G8: 45938 | H8: 45944 | I8: 1500 | J8: 1500 | K8: =I8 - J8 -> 0 | L8: Shadi | M8: =TEXT(G8,"YYYY-MM") -> 2025-10
A9: 2025/008 | B9: Pooja | C9: 8856107653 | D9: Female | E9: Lehanga | F9: Sell | G9: 45941 | H9: 45947 | I9: 1100 | J9: 500 | K9: =I9 - J9 -> 600 | L9: diwali design | M9: =TEXT(G9,"YYYY-MM") -> 2025-10
A10: 2025/009 | B10: Manisha | C10: 7665712012 | D10: Female | E10: Kurta | F10: Sell | G10: 45902 | H10: 45906 | I10: 700 | J10: 700 | K10: =I10 - J10 -> 0 | L10: navratri design | M10: =TEXT(G10,"YYYY-MM") -> 2025-09
A11: 2025/010 | B11: Kajol meghwanshi | C11: 7024027564 | D11: Female | E11: Kurta | F11: Sell | G11: 31/09/2025 | H11: 45934 | I11: 1000 | J11: 1000 | K11: =I11 - J11 -> 0 | L11: navratri design | M11: =TEXT(G11,"YYYY-MM") -> 31/09/2025
A12: 2025/011 | B12: Bhawana | C12: 9571268223 | D12: Female | E12: Kurta | F12: Sell | G12: 45922 | H12: 45924 | I12: 2000 | J12: 1000 | K12: =I12 - J12 -> 1000 | L12: navratri design | M12: =TEXT(G12,"YYYY-MM") -> 2025-09
A13: 2025/012 | B13: Widhi sawiyani | C13: 7427004028 | D13: Female | E13: Top | F13: Sell | G13: 45864 | H13: 45868 | I13: 1500 | J13: 700 | K13: =I13 - J13 -> 800 | L13: casual | M13: =TEXT(G13,"YYYY-MM") -> 2025-07
A14: 2025/013 | B14: Shubhangi | C14: 7340148101 | D14: Female | E14: Lehanga | F14: Rent | G14: 45893 | H14: 45899 | I14: 1700 | J14: 1000 | K14: =I14 - J14 -> 700 | L14: Shadi | M14: =TEXT(G14,"YYYY-MM") -> 2025-08
A15: 2025/014 | B15: Vandana | C15: 7782806612 | D15: Female | E15: Kurta | F15: Sell | G15: 45917 | H15: 45924 | I15: 1200 | J15: 500 | K15: =I15 - J15 -> 700 | L15: casual | M15: =TEXT(G15,"YYYY-MM") -> 2025-09
A16: 2025/015 | B16: Rose | C16: 9828008912 | D16: Female | E16: Gown | F16: Sell | G16: 45950 | H16: 45958 | I16: 3000 | J16: 2000 | K16: =I16 - J16 -> 1000 | L16: diwali design | M16: =TEXT(G16,"YYYY-MM") -> 2025-10
A17: 2025/016 | B17: Chavi Jain | C17: 8005961045 | D17: Female | E17: Lehanga | F17: Sell | G17: 45945 | H17: 45947 | I17: 3250 | J17: 1750 | K17: 1500 | L17: diwali design | M17: =TEXT(G17,"YYYY-MM") -> 2025-10
A18: 2025/017 | B18: Manda | C18: -- | D18: Male | E18: Pant | F18: Sell | G18: 45933 | H18: 45936 | I18: 400 | J18: 200 | K18: =I18 - J18 -> 200 | L18: navratri design | M18: =TEXT(G18,"YYYY-MM") -> 2025-10
A19: 2025/018 | B19: Rinku | C19: 7300127553 | D19: Female | E19: Lehanga | F19: Sell | G19: 45925 | H19: 45934 | I19: 400 | J19: 400 | K19: =I19 - J19 -> 0 | L19: navratri design | M19: =TEXT(G19,"YYYY-MM") -> 2025-09
A20: 2025/019 | B20: Sanya | C20: 8944340887 | D20: Female | E20: Gown | F20: Sell | G20: 45940 | H20: 45946 | I20: 3300 | J20: 2000 | K20: =I20 - J20 -> 1300 | L20: diwali design | M20: =TEXT(G20,"YYYY-MM") -> 2025-10
A21: 2025/020 | B21: Lekha | C21: -- | D21: Female | E21: Shirt | F21: Sell | G21: 45907 | H21: 45914 | I21: 800 | J21: 600 | K21: =I21 - J21 -> 200 | L21: casual | M21: =TEXT(G21,"YYYY-MM") -> 2025-09
A22: 2025/021 | B22: Bhavisha(Ritu) | C22: 7576124087 | D22: Female | E22: Lehanga | F22: Sell | G22: 45920 | H22: 45930 | I22: 1800 | J22: 1000 | K22: =I22 - J22 -> 800 | L22: Shadi | M22: =TEXT(G22,"YYYY-MM") -> 2025-09
A23: 2025/022 | B23: Anehal kumari | C23: 9892233012 | D23: Female | E23: Gown | F23: Sell | G23: 45951 | H23: 45962 | I23: 3300 | J23: 2000 | K23: =I23 - J23 -> 1300 | L23: diwali design | M23: =TEXT(G23,"YYYY-MM") -> 2025-10
A24: 2025/023 | B24: Harshita | C24: 9852361228 | D24: Female | E24: Kurta | F24: Sell | G24: 45911 | H24: 45915 | I24: 1000 | J24: 500 | K24: =I24 - J24 -> 500 | M24: =TEXT(G24,"YYYY-MM") -> 2025-09
A25: 2025/024 | B25: Nikita | C25: 7624320149 | D25: Female | E25: Gown | F25: Sell | G25: 45914 | H25: 45918 | I25: 2500 | J25: 1500 | K25: =I25 - J25 -> 1000 | M25: =TEXT(G25,"YYYY-MM") -> 2025-09
A26: 2025/025 | B26: Kavita | C26: 9079981782 | D26: Female | E26: Lehanga | F26: Sell | G26: 45815 | H26: 45822 | I26: 3300 | J26: 1000 | K26: =I26 - J26 -> 2300 | L26: chinon dupata | M26: =TEXT(G26,"YYYY-MM") -> 2025-06
A27: 2025/026 | B27: Pari | C27: 9928541145 | D27: Female | E27: Gown | F27: Sell | G27: 45865 | H27: 45868 | I27: 3700 | J27: 1300 | K27: =I27 - J27 -> 2400 | M27: =TEXT(G27,"YYYY-MM") -> 2025-07
A28: 2025/027 | B28: khushi | C28: 9877280877 | D28: Female | E28: Lehanga | F28: Rent | G28: 45828 | H28: 45832 | I28: 1200 | J28: 1000 | K28: =I28 - J28 -> 200 | L28: green lehanga | M28: =TEXT(G28,"YYYY-MM") -> 2025-06
A29: 2025/028 | B29: Komal | C29: 9832454875 | D29: Female | E29: Kurta | F29: Sell | G29: 45848 | H29: 45852 | I29: 800 | J29: 400 | K29: =I29 - J29 -> 400 | L29: casual | M29: =TEXT(G29,"YYYY-MM") -> 2025-07
A30: 2025/029 | B30: Sonia | C30: 9821032012 | D30: Female | E30: Lehanga | F30: Sell | G30: 45933 | H30: 45938 | I30: 3200 | J30: 1500 | K30: =I30 - J30 -> 1700 | L30: shadi | M30: =TEXT(G30,"YYYY-MM") -> 2025-10
A31: 2025/030 | B31: Priyanka | C31: 9773808712 | D31: Female | E31: Kurta | F31: Sell | G31: 45909 | H31: 45913 | I31: 900 | J31: 500 | K31: =I31 - J31 -> 400 | L31: casual | M31: =TEXT(G31,"YYYY-MM") -> 2025-09
A32: 2025/031 | B32: Kajol | C32: 7665777899 | D32: Female | E32: Gown | F32: Sell | G32: 45945 | H32: 45948 | I32: 3000 | J32: 2000 | K32: =I32 - J32 -> 1000 | L32: birthday | M32: =TEXT(G32,"YYYY-MM") -> 2025-10
A33: 2025/032 | B33: pankhuri | C33: 7982808778 | D33: Female | E33: Gown | F33: Rent | G33: 45946 | H33: 45950 | I33: 1500 | J33: 1000 | K33: =I33 - J33 -> 500 | L33: shadi | M33: =TEXT(G33,"YYYY-MM") -> 2025-10
A34: 2025/033 | B34: Kajol | C34: 7728089877 | D34: Female | E34: Kurta | F34: Sell | G34: 45890 | H34: 45897 | I34: 1200 | J34: 600 | K34: =I34 - J34 -> 600 | L34: casual | M34: =TEXT(G34,"YYYY-MM") -> 2025-08
A35: 2025/034 | B35: Simran | C35: 9935267592 | D35: Female | E35: Lehanga top | F35: Sell | G35: 45891 | H35: 45889 | I35: 1300 | J35: 600 | K35: =I35 - J35 -> 700 | L35: anchoring | M35: =TEXT(G35,"YYYY-MM") -> 2025-08
A36: 2025/035 | B36: Sanjana | C36: 7289374659 | D36: Female | E36: Kurta | F36: Sell | G36: 45910 | H36: 45926 | I36: 900 | J36: 500 | K36: =I36 - J36 -> 400 | L36: casual | M36: =TEXT(G36,"YYYY-MM") -> 2025-09
A37: 2025/036 | B37: Jaya | C37: 7642989323 | D37: Female | E37: Kurta | F37: Sell | G37: 45912 | H37: 45914 | I37: 1350 | J37: 800 | K37: =I37 - J37 -> 550 | L37: casual | M37: =TEXT(G37,"YYYY-MM") -> 2025-09
A51: Month | B51: No. of Orders | C51: Total Revenue | D51: No. of Days of Operation | E51: Avg. Revenue/Day
A52: 45809 | B52: 4 | C52: 4500 | D52: 10 | E52: =C52/D52 -> 450
A53: 45839 | B53: 7 | C53: 6000 | D53: 31 | E53: =C53/D53 -> 193.54839
...

Sheet Tailor Sheet
A1: Form No. | B1: Booking Date | C1: Delivery Date | D1: Bust | E1: Waist | F1: Hip | G1: Shoulder | H1: Waist Length | I1: Round Arm | J1: L Waist | K1: Sleeve Length | L1: Skirt Length | M1: Pant Length | N1: Lehenga Length | O1: Round Bottom | P1: Round Leg | Q1: Round Waist
A2: 2025/001 | B2: 45908 | C2: 45650 | D2: 39 | E2: 28 | F2: 27-28 | G2: 36 | H2: 30 | L2: 42 | N2: 42
A3: 2025/002 | B3: 44774 | C3: 45668 | D3: 39 | E3: 30 | F3: 29-30 | G3: 33 | H3: 31 | L3: 40
A4: 2025/003 | B4: 45644 | C4: 45682 | D4: 33 | E4: 24 | F4: 27-28 | G4: 30 | H4: 28 | I4: 6
A5: 2025/004 | B5: 45677 | C5: 45868 | D5: 36 | E5: 29 | F5: 29-30 | G5: 32 | H5: 20 | I5: 5 | J5: 20
A6: 2025/005 | B6: 45668 | C6: 45875 | D6: 33 | E6: 27
A7: 2025/006 | B7: 45948 | C7: 45899 | D7: 35 | E7: 24
A8: 2025/007 | B8: 45938 | C8: 45906 | D8: 39 | E8: 26
A9: 2025/008 | B9: 45941 | C9: 45911 | D9: 34 | E9: 24
A10: 2025/009 | B10: 45902 | C10: 45914 | D10: 29 | E10: 29
A11: 2025/010 | B11: 31/09/2025 | C11: 45915 | D11: 31 | E11: 30
A12: 2025/011 | B12: 45922 | C12: 45924 | D12: 27 | E12: 31
A13: 2025/012 | B13: 45864 | C13: 45930 | D13: 28 | E13: 27
A14: 2025/013 | B14: 45893 | C14: 45934 | D14: 30 | E14: 28
A15: 2025/014 | B15: 45917 | C15: 45934 | D15: 39 | E15: 25
A16: 2025/015 | B16: 45950 | C16: 45936 | D16: 33 | E16: 29
A17: 2025/016 | B17: 45945 | C17: 45944 | D17: 29 | E17: 24
A18: 2025/017 | B18: 45933 | C18: 45946 | D18: 27 | E18: 22
A19: 2025/018 | B19: 45925 | C19: 45947 | D19: 25 | E19: 27
A20: 2025/019 | B20: 45940 | C20: 45947 | D20: 39 | E20: 30
A21: 2025/020 | B21: 45907 | C21: 45950 | D21: 33 | E21: 29
A22: 2025/021 | B22: 45920 | C22: 45958 | D22: 36 | E22: 30
A23: 2025/022 | B23: 45951 | C23: 45962 | D23: 35 | E23: 31
A24: 2025/023 | B24: 45911 | C24: --
A25: 2025/024 | B25: 45912
A26: 2025/025 | B26: 45913
A27: 2025/026 | B27: 45914
A28: 2025/027 | B28: 45915
A29: 2025/028 | B29: 45916
A30: 2025/029 | B30: 45917
A31: 2025/030 | B31: 45918
A32: 2025/031 | B32: 45919
A33: 2025/032 | B33: 45920
A34: 2025/033 | B34: 45921
A35: 2025/034 | B35: 45922
A36: 2025/035 | B36: 45923
... A50: 2025/049 | B50: 45937

Sheet Statistics
A1: Metric / Field | B1: Count | C1: Mean | D1: Median | E1: Mode | F1: Standard Deviation | G1: Min | H1: Max | X1: Dress Type | Y1: Order Type | Z1: Booking Date
A2: Total Amount (₹) | B2: =COUNT('Customer information'!I2:I27) -> 26 | C2: =AVERAGE('Customer information'!I2:I27) -> 1881.3462 | D2: =MEDIAN('Customer information'!I2:I27) -> 1705 | E2: =_xlfn.MODE.SNGL('Customer information'!I2:I27) -> 1000 | F2: =_xlfn.STDEV.P('Customer information'!I2:I27) -> 971.68723 | G2: 1000 | H2: 8500 | X2: Gown (Sinner Lycra Fabric) | Y2: Sell | Z2: 45908
A3: Advance Paid (₹) | B3: =COUNT('Customer information'!J2:J27) -> 26 | C3: =AVERAGE('Customer information'!J2:J27) -> 1057.6923 | D3: =MEDIAN('Customer information'!J2:J27) -> 1000 | E3: =_xlfn.MODE.SNGL('Customer information'!J2:J27) -> 1000 | F3: =_xlfn.STDEV.P('Customer information'!J2:J27) -> 530.54622 | G3: 300 | H3: 4000 | X3: onepiece | Y3: Sell | Z3: 45870
A4: Amount Due (₹) | B4: Low Spread | C4: Low | F4: 0 | G4: 2500 | X4: Serews | Y4: Sell | Z4: 45948
A5: Turnaround Time | B5: 4–14 days | C5: 7 days | D5: =MEDIAN('Customer information'!K2:K27) -> 750 | E5: =_xlfn.MODE.SNGL('Customer information'!K2:K27) -> 0 | F5: Moderate | G5: 3 | H5: 15 | X5: lehanga top | Y5: Sell | Z5: 45920
X6: Lehanga top | Y6: Rent | Z6: 45911
X7: Kurta | Y7: Sell | Z7: 45948
X8: Gown | Y8: Sell | Z8: 45938
X9: Lehanga | Y9: Sell | Z9: 45941
X10: Kurta | Y10: Sell | Z10: 45902
X11: Kurta | Y11: Sell | Z11: 31/09/2025
X12: Kurta | Y12: Sell | Z12: 45922
X13: Top | Y13: Sell | Z13: 45864
X14: Lehanga | Y14: Rent | Z14: 45893
X15: Kurta | Y15: Sell | Z15: 45917
X16: Gown | Y16: Sell | Z16: 45950
X17: Lehanga | Y17: Sell | Z17: 45945
X18: Pant | Y18: Sell | Z18: 45933
X19: Lehanga | Y19: Sell | Z19: 45925
X20: Gown | Y20: Sell | Z20: 45940
X21: Shirt | Y21: Sell | Z21: 45907
X22: Lehanga | Y22: Sell | Z22: 45920
X23: Gown | Y23: Sell | Z23: 45951
... X37: Kurta | Y37: Sell | Z37: 45912

Sheet Chart1 Monthly Total Revenue (B
A1: Based on the customer and order information, here is an analysis of the key trends and insights from your data. Key Takeaways The data shows a strong upward trend in business activity and a clear focus on 'Sell' orders for specific types of clothing, with substantial outstanding payments that may need attention. 1. Significant and Accelerating Revenue Growth The business has shown remarkable growth in total revenue from June to October 2025, indicating strong market acceptance and increasing customer traffic. • Sharp Increase: Total monthly revenue grew from 4,500 in June to 27,250 in October 2025, showing a substantial positive trend over the five-month period. • Total Financials: Across all orders, the total revenue is 64,265, with 36,400 paid as advance and 27,865 remaining as the total amount due. • Average Order Value: The average total order value is 1,785.14. 2. High Concentration in 'Sell' Orders and Specific Dress Types The business model is heavily weighted toward selling garments rather than renting, and revenue is driven by a few key product categories. • Dominant Order Type: 'Sell' orders account for nearly 89% of all transactions (32 orders), while 'Rent' accounts for only 11% (4 orders). This suggests that the primary focus should be on optimizing the selling process and inventory. • Top Products: The most popular items are kurta (11 orders), gown (8 orders), and lehanga (8 orders), which together comprise a majority of the sales volume. 3. Focus on Managing Outstanding Payments The total outstanding balance represents a considerable portion of the business's potential cash flow, highlighting a need for a robust follow-up system. • Amount Due: The total outstanding amount across all orders is 27,865. • Cash Flow Opportunity: Collecting the total amount due could increase the business's cash reserves by approximately 76.5% of the total advance payments received (27,865 due vs. 36,400 advance paid). Monthly Total Revenue Trend The chart below visualizes the strong upward trend in total revenue from June to October 2025. Monthly Total Revenue (Booking Date) The line chart shows a clear, consistent increase in total revenue month-over-month. (See chart: monthly_total_revenue_chart.json)
A3: Booking Date Month Start | B3: Total Amount
A4: 45809 | B4: 4500 | D4: Product Category | E4: Order Count | F4: Total Revenue | G4: Inventory Strategy Implication
A5: 45839 | B5: 6000 | D5: Gown | E5: 9 | F5: 23510 | G5: Highest-Value, **Make-to-Stock/Order** for High-Demand Designs
A6: 45870 | B6: 6755 | D6: Lehenga | E6: 8 | F6: 15950 | G6: High Volume/Value, Focus on **Diversifying Designs**
A7: 45901 | B7: 18760 | D7: Kurta | E7: 10 | F7: 12150 | G7: Highest Volume, **High-Priority Stocking**
A8: 45931 | B8: 27250 | D8: Lehenga Top | E8: 3 | F8: 4800 | G8: Lower Volume, Monitor as **Potential Upsell Component**

Sheet Sheet4
A1: Order Type | B1: Total Orders | C1: Avg. Order Value | D1: Financial Strategy Implication
A2: Sell | B2: 31 | C2: 1866.61 | D2: Main Focus. **Requires robust materials/component inventory.**
A3: Rent | B3: 4 | C3: 1350 | D3: Niche. **Requires separate maintenance/cleaning/storage processes.**
D4: Standard Dress Type | E4: Average Lead Time (Days) | F4: Range (Min - Max Days) | G4: Inventory & Sales Implication
D5: Lehenga | E5: 6.1 | F5: 2 - 10 | G5: Highest average Lead Time: **Requires larger stock or earlier customer communication.**
D6: Kurta | E6: 5.2 | F6: 2 - 16 | G6: Highest Max Lead Time: **High risk of customer dissatisfaction; needs process review.**
D7: Lehenga Top | E7: 1 | F7: -2 - 5 | G7: Can be fulfilled fastest: **Good candidates for "Ready-to-Wear" stock.**

Sheet Sheet5
A1: Month (2025) | B1: Total Revenue (₹) | C1: Monthly Growth Rate (%)
A2: 45809 | B2: 4500 | C2: "N/A"
A3: 45839 | B3: 6000 | C3: "33.33"
A4: 45870 | B4: 6755 | C4: "12.58"
A5: 45901 | B5: 18760 | C5: "177.74"
A6: 45931 | B6: 27250 | C6: "45.26"
A8: Monthly Revenue Pattern:
